Workbook

Sheet النظافة
A1: جمهورية مصر العربية | M1: Arab Republic of Egypt
A2: الهيئة العامة للرعاية الصحية | M2: General Authority of Health Care
A3: مجمع الفيروز الطبي | M3: AL Fayrouz Medical Complex
A6: مراقبة وتقييم عقد النظافة
B7: البند | C7: 3/2026 | D7: 6/2026 | E7: 9/2026
A8: 1 | B8: عدم الالتزام بالمظهر ىالعام ( الزى الكامل - عدم حلاقة الذقن - كارت التعريف - نظافة شخصية) | C8: 1 | D8: 1 | E8: 0
A9: 2 | B9: عدم الالتزام بعدد العمالة المحددة | C9: 0 | D9: 0 | E9: 1
A10: 3 | B10: في حالة تجاوز نسبة الغياب عن 25 % من اجمالي الفراد بالوردية ( لا تطبق في الحالات التى يكون عدد العاملين بالوردية اقل من 4 افراد ) | C10: 1 | D10: 1 | E10: 1
A11: 4 | B11: تجاوز نسبة العجز الشهرى لعدد الأفراد والمشرفين عن 25% من العدد المطلوب طبقا للعقد | C11: 1 | D11: 1 | E11: 1
A12: 5 | B12: عدم الالتزام بتوفير الاجهزة والمعدات المتفق عليها أو التاخر في الإصلاح | C12: 1 | D12: 1 | E12: 1
A13: 6 | B13: مزاولة اى من الأفراد أو المشرفين لعمل غير المخصص لهم داخل الجهة | C13: 1 | D13: 1 | E13: 1
A14: 7 | B14: قيام أحد الأفراد أو المشرفين بالتعامل بأسلوب غير لائق مع العاملين بالجهة او الزائرين او المرضي | C14: 1 | D14: 1 | E14: 1
A15: 8 | B15: استمرار الفرد او المشرف لاكثر من وردية بالموقع او العمل أكثر من 12 ساعة يومياً | C15: 1 | D15: 1 | E15: 1
A16: 9 | B16: في حالة وجود سوابق جنائية لأحد الافراد او المشرفين | C16: 1 | D16: 1 | E16: 1
A17: 10 | B17: الحاق أو إنهاء عمل أو نقل أي فرد من الأفراد أو المشرفين دون الرجوع لإدارة الشئون الإدارية بالجهة | C17: 1 | D17: 1 | E17: 1
A18: 11 | B18: نوم أو تكاسل أحد الأفراد أو المشرفين أثناء الخدمة | C18: 0 | D18: 1 | E18: 1
A19: 12 | B19: عدم الإلتزام بتقديم كشف يومية الأعداد لكل وردية على حدة مذكورا به اسم المشرف وأسماء الأفراد المتواجدين فعلياً بالوردية وأماكن تواجدهم وبحد أقصى ساعة من بداية الوردية | C19: 1 | D19: 1 | E19: 1
A20: 13 | B20: في حالة عدم التزام الشركة بوضع ىخطة للقيام بأعمال النظافة اللازمة للمنشأة بكامل مرافقه والمداخل والمخارج وطريقة الإإشراف عليها وآليه توزيع الأعداد اللازمة خلال كل كل وردية لتنفيذ هذه الخطة على مدار الورديتين في حدود العدد المطلوب تعتمد من مدير إدارة الشئون الإدارية بالجهة أو من ينوب عن كل منها وتسلم شهريا قبل بداية كل شهر بثلاث ايام على الأقل | C20: 1 | D20: 1 | E20: 1
A21: 14 | B21: في حالة عدم التزام الشركة بوضع وتنفيذ خطة لتدريب 20 % من الأفراد شهريا على اعمال النظافة وشئون البيئة وكيفية التعامل مع مختلف الأقسام طبقاً لطبيعة كل قسم | C21: 1 | D21: 1 | E21: 1
A22: 15 | B22: تشغيل عمال أقل من 18 عام وأكبر من 50 سنة | C22: 0 | D22: 1 | E22: 1
A23: 16 | B23: تعامل احد أفراد الشركة المتعاقدة مع المريض أو مرافقيه خارج نطاق الأعمال المكلف بها | C23: 1 | D23: 1 | E23: 1
A24: 17 | B24: عدم التزام الشركة المتعاقدة بتوفير الخامات والموارد طبقا لمت تم الاتفاق عليه بالتعاقد | C24: 1 | D24: 1 | E24: 1
A25: 18 | B25: تأخر الأفراد أو المشرفين عن الحضور في المواعيد المحددة | C25: 1 | D25: 1 | E25: 1
A26: 19 | B26: قيام الشركة بتشغيل اى من العاملين بالمنشاة أو تشغيل أبناء العاملين بذات المنشاة | C26: 1 | D26: 1 | E26: 1
A27: 20 | B27: عدم تنظيف واجهات مبانى المنشأت وفقا لما هو منصوص عليه بالكراسىة | C27: 1 | D27: 0 | E27: 0
A28: 21 | B28: عدم تواجد الفرد أو المشرف في المنطقة المكلف بتقديم الخدمة فيها | C28: 1 | D28: 1 | E28: 1
A29: 22 | B29: استخدام أدوات او معدات غير مطابقة للمواصفات الفنية المتفق عليها في التعاقد في اعمال النظافة اليومية | C29: 1 | D29: 1 | E29: 1
A30: 23 | B30: في حالة عدم التزام الشركة بتقديم كامل المستندات الخاصة بكل فرد من أفرادها والمتفق عليها بالتعاقد | C30: 1 | D30: 1 | E30: 1
... A32: 25 | B32: قيام العاملين بالشركة بمخالفة أي شرط من الشروط الخاصة الواردة بهذه الكراسة والغير منصوص عليها بجدول المخالفات | C32: 1 | D32: 1 | E32: 1
A33: النسبة الإجمالية | C33: 0.88 | D33: 0.92 | E33: 0.96 | F33: =IFERROR(AVERAGE(F19:F32),"-") -> - | G33: =IFERROR(AVERAGE(G19:G32),"-") -> - | H33: =IFERROR(AVERAGE(H19:H32),"-") -> - | I33: =IFERROR(AVERAGE(I19:I32),"-") -> - | J33: =IFERROR(AVERAGE(J19:J32),"-") -> - | K33: =IFERROR(AVERAGE(K19:K32),"-") -> - | L33: =IFERROR(AVERAGE(L19:L32),"-") -> - | M33: =IFERROR(AVERAGE(M19:M32),"-") -> -

Sheet     Chart    
A1: جمهورية مصر العربية | M1: Arab Republic of Egypt
A2: الهيئة العامة للرعاية الصحية | M2: General Authority of Health Care
A3: مجمع الفيروز الطبي | M3: Sharm International Hospital
A6: مراقبة وتقييم عقد النظافة
A8: البسط | B8: عدد بنود التقييم المحققة
A9: المقام | B9: إجمالي عدد بنود التقييم (المحددة)
A10: المستهدف | B10: 0.8
A12: الشهر | B12: البسط | C12: المقام | D12: النسبة
A13: 3/2026 | B13: =SUMPRODUCT(--('النظافة'!$C$8:$C$32&""="1")) -> 22 | C13: =SUMPRODUCT(--('النظافة'!$C$8:$C$32&""="1"))+SUMPRODUCT(--('النظافة'!$C$8:$C$32&""="0")) -> 25 | D13: =IFERROR(B13/C13,"") -> 0.88
A14: 6/2026 | B14: =SUMPRODUCT(--('النظافة'!$D$8:$D$32&""="1")) -> 23 | C14: =SUMPRODUCT(--('النظافة'!$D$8:$D$32&""="1"))+SUMPRODUCT(--('النظافة'!$D$8:$D$32&""="0")) -> 25 | D14: =IFERROR(B14/C14,"") -> 0.92
A15: 9/2026 | B15: =SUMPRODUCT(--('النظافة'!$E$8:$E$32&""="1")) -> 23 | C15: =SUMPRODUCT(--('النظافة'!$E$8:$E$32&""="1"))+SUMPRODUCT(--('النظافة'!$E$8:$E$32&""="0")) -> 25 | D15: =IFERROR(B15/C15,"") -> 0.92
D16: =IFERROR(B16/C16,"")
D17: =IFERROR(B17/C17,"")
D18: =IFERROR(B18/C18,"")
D19: =IFERROR(B19/C19,"")
D20: =IFERROR(B20/C20,"")
D21: =IFERROR(B21/C21,"")
D22: =IFERROR(B22/C22,"")
D23: =IFERROR(B23/C23,"")
A24: إجمالي التقييم السنوي للعقد | D24: =AVERAGE(D13:D23) -> 0.90666667
A26: الشهر | B26: التحليل الوصفي | E26: الإجراء التصحيحي | K26: المسؤول عن التنفيذ | M26: المدة

Sheet الأكسجين
A1: جمهورية مصر العربية | L1: Arab Republic of Egypt
A2: الهيئة العامة للرعاية الصحية | L2: General Authority of Health Care
A3: مجمع الفيروز الطبي | L3: AL Fayrouz Medical Complex
A6: مراقبة وتقييم عقد أعمال الأكسجين الطبي السائل
A7: م | B7: البند | C7: التقييم (ربع سنوي)
C8: 3/2026 | D8: 6/2026 | E8: 9/2026
A9: 1 | B9: الالتزام بتوريد سائل الاكسجين طبى معبأ بدرجة نقاوة لا تقل عن 99.7% لسائل الاكسجين طبقا للمواصفات القياسية المصرية وتعبئة اسطوانات الاكسجين 40 و10 لتر | C9: 1 | D9: 1 | E9: 1
A10: 2 | B10: الالتزام بتامين المعدات فضلا عن توفير المساعدة التى نحتاجها لفحص المعدات وصيانتها | C10: 1 | D10: 1 | E10: 1
A11: 3 | B11: التزام الطرف الثاني بالتوريد خلال 48 ساعة بإبلاغ خدمة العملاء بخلاف الحالات الطارئة في حينه | C11: 1 | D11: 1 | E11: 1
A12: النسبة الإجمالية | C12: =IFERROR(AVERAGE(C9:C11),"-") -> 1 | D12: =IFERROR(AVERAGE(D9:D11),"-") -> 1 | E12: =IFERROR(AVERAGE(E9:E11),"-") -> 1 | F12: =IFERROR(AVERAGE(F9:F11),"-") -> - | G12: =AVERAGE(G9:G11) -> #DIV/0! | H12: =IFERROR(AVERAGE(H9:H11),"-") -> - | I12: =IFERROR(AVERAGE(I9:I11),"-") -> - | J12: =IFERROR(AVERAGE(J9:J11),"-") -> - | K12: =AVERAGE(K9:K11) -> #DIV/0! | L12: =AVERAGE(L9:L11) -> #DIV/0! | M12: =IFERROR(AVERAGE(M9:M11),"-") -> -

Sheet      Chart    
A1: جمهورية مصر العربية | P1: Arab Republic of Egypt
A2: الهيئة العامة للرعاية الصحية | P2: General Authority of Health Care
A3: مجمع الفيروز الطبي | O3: AL Fayrouz Medical Complex
A6: مراقبة وتقييم عقد أعمال الأكسجين الطبي السائل
A8: البسط | B8: عدد بنود التقييم المحققة
A9: المقام | B9: إجمالي عدد بنود التقييم (المحددة)
A10: المستهدف | B10: 0.8
A12: الشهر | B12: البسط | C12: المقام | D12: النسبة
A13: 3/2026 | B13: =SUMPRODUCT(--('الأكسجين'!$C$9:$C$11&""="1")) -> 3 | C13: =SUMPRODUCT(--('الأكسجين'!$C$9:$C$11&""="1"))+SUMPRODUCT(--('الأكسجين'!$C$9:$C$11&""="0")) -> 3 | D13: =IFERROR(B13/C13,"") -> 1
A14: 6/2026 | B14: =SUMPRODUCT(--('الأكسجين'!$D$9:$D$11&""="1")) -> 3 | C14: =SUMPRODUCT(--('الأكسجين'!$D$9:$D$11&""="1"))+SUMPRODUCT(--('الأكسجين'!$D$9:$D$11&""="0")) -> 3 | D14: =IFERROR(B14/C14,"") -> 1
A15: 9/2026 | B15: =SUMPRODUCT(--('الأكسجين'!$E$9:$E$11&""="1")) -> 3 | C15: =SUMPRODUCT(--('الأكسجين'!$E$9:$E$11&""="1"))+SUMPRODUCT(--('الأكسجين'!$E$9:$E$11&""="0")) -> 3 | D15: =IFERROR(B15/C15,"") -> 1
D16: =IFERROR(B16/C16,"")
D17: =IFERROR(B17/C17,"")
D18: =IFERROR(B18/C18,"")
D19: =IFERROR(B19/C19,"")
D20: =IFERROR(B20/C20,"")
D21: =IFERROR(B21/C21,"")
D22: =IFERROR(B22/C22,"")
D23: =IFERROR(B23/C23,"")
A24: إجمالي التقييم السنوي للعقد | D24: =AVERAGE(D13:D23) -> 1
A26: الشهر | B26: التحليل الوصفي | E26: الإجراء التصحيحي | K26: المسؤول عن التنفيذ | M26: المدة
E27: - | K27: - | M27: -
E28: - | K28: - | M28: -
E29: - | K29: - | M29: -
E30: - | K30: - | M30: -
E31: - | K31: - | M31: -
K32: - | M32: -
E33: - | K33: - | M33: -
E34: - | K34: - | M34: -
E35: - | K35: - | M35: -
E36: - | K36: - | M36: -
E37: - | K37: - | M37: -

Sheet الأمن والحراسة
A1: جمهورية مصر العربية | M1: Arab Republic of Egypt
A2: الهيئة العامة للرعاية الصحية | M2: General Authority of Health Care
A3: مجمع الفيروز الطبي | M3: AL Fayrouz Medical Complex
A6: مراقبة وتقييم عقد الأمن والحراسة
A7: م | B7: البند
C8: 3/2026 | D8: 6/2026 | E8: 9/2026
A9: 1 | B9: توفير العمالة اللازمة والمدربة لأعمال الامن والحراسة | C9: 1 | D9: 1 | E9: 1
A10: 2 | B10: التزام العاملين بالزي الرسمي والمظهر العام | C10: 1 | D10: 1 | E10: 1
A11: 3 | B11: عدم وجود عجز الشفت الأول و الثاني و الثالث من الافراد | C11: 1 | D11: 1 | E11: 1
A12: 4 | B12: الالتزام بعدم حدوث تجاوز نسبة الغياب بالوردية الواحدة عن 25% من اجمالى الوردية | C12: 1 | D12: 1 | E12: 1
A13: 5 | B13: الالتزام بادخال الزائرين فقط بمواعيد الزيارات | C13: 1 | D13: 1 | E13: 0
A14: 6 | B14: حراسة وتأمين الجهة بالكامل فيما هو واقع داخل اسوار المستشفى بكامل البناء والحدود الاربعة وجميع مايخص الجهة مع تأمين اى ممتلكات أو معدات أو اجهزة أو مستلزمات تخص المستشفى وكذلك تأمين أى مبانى ملحقة بالمستشفى سواء داخل حدودها أو فى مكان اخر | C14: 1 | D14: 1 | E14: 1
A15: 7 | B15: توفير المعدات والاجهزة الازمة لتنفيذ الاعمال | C15: 1 | D15: 1 | E15: 1
A16: 8 | B16: الالتزام بعدم السماح لغير المصرح لهم بالدخول الي داخل حدود المستشفي ( الباعة , المندوبين , ....... ) | C16: 1 | D16: 1 | E16: 1
A17: 9 | B17: جلوس مرضي او زوار داخل المربعات الخضراء | C17: 1 | D17: 1 | E17: 1
A18: 10 | B18: عدم دخول اطعمه من الخارج او مندوبين توصيل الطلبات | C18: 1 | D18: 1 | E18: 1
A19: 11 | B19: مزاولة أفراد الأمن لأعمال غير مصرح لهم بها | C19: 1 | D19: 1 | E19: 1
A20: 12 | B20: انتظار السيارات في الأماكن الغير مخصصة | C20: 0 | D20: 1 | E20: 1
... A22: 14 | B22: الالتزام بعدم حدوث تعامل غير لائق و تصرفات لا تتناسب مع السلوك و الاداب العامة و في حالة حدوث يتم الاستبعاد يتم الاستبعاد و تعيين بديل خلال 48 ساعة | C22: 1 | D22: 1 | E22: 1
A23: النسبة الإجمالية | C23: =IFERROR(AVERAGE(C9:C22),"-") -> 0.92857143 | D23: =IFERROR(AVERAGE(D9:D22),"-") -> 0.92857143 | E23: =IFERROR(AVERAGE(E9:E22),"-") -> 0.92857143 | F23: =IFERROR(AVERAGE(F9:F22),"-") -> - | G23: =IFERROR(AVERAGE(G9:G22),"-") -> - | H23: =IFERROR(AVERAGE(H9:H22),"-") -> - | I23: =IFERROR(AVERAGE(I9:I22),"-") -> - | J23: =IFERROR(AVERAGE(J9:J22),"-") -> - | ... M23: =IFERROR(AVERAGE(M9:M22),"-") -> -

Sheet   Chart    
A1: جمهورية مصر العربية | M1: Arab Republic of Egypt
A2: الهيئة العامة للرعاية الصحية | M2: General Authority of Health Care
A3: مجمع الفيروز الطبي | M3: AL Fayrouz Medical Complex
A6: مراقبة وتقييم عقد الأمن والحراسة
A8: البسط | B8: عدد بنود التقييم المحققة
A9: المقام | B9: إجمالي عدد بنود التقييم (المحددة)
A10: المستهدف | B10: 0.8
A12: الشهر | B12: البسط | C12: المقام | D12: النسبة
A13: 3/2026 | B13: =SUMPRODUCT(--('الأمن والحراسة'!$C$9:$C$22&""="1")) -> 13 | C13: =SUMPRODUCT(--('الأمن والحراسة'!$C$9:$C$22&""="1"))+SUMPRODUCT(--('الأمن والحراسة'!$C$9:$C$22&""="0")) -> 14 | D13: =IFERROR(B13/C13,"") -> 0.92857143
A14: 6/2026 | B14: =SUMPRODUCT(--('الأمن والحراسة'!$D$9:$D$22&""="1")) -> 13 | C14: =SUMPRODUCT(--('الأمن والحراسة'!$D$9:$D$22&""="1"))+SUMPRODUCT(--('الأمن والحراسة'!$D$9:$D$22&""="0")) -> 14 | D14: =IFERROR(B14/C14,"") -> 0.92857143
A15: 9/2026 | B15: =SUMPRODUCT(--('الأمن والحراسة'!$E$9:$E$22&""="1")) -> 13 | C15: =SUMPRODUCT(--('الأمن والحراسة'!$E$9:$E$22&""="1"))+SUMPRODUCT(--('الأمن والحراسة'!$E$9:$E$22&""="0")) -> 14 | D15: =IFERROR(B15/C15,"") -> 0.92857143
D16: =IFERROR(B16/C16,"")
D17: =IFERROR(B17/C17,"")
D18: =IFERROR(B18/C18,"")
D19: =IFERROR(B19/C19,"")
D20: =IFERROR(B20/C20,"")
D21: =IFERROR(B21/C21,"")
D22: =IFERROR(B22/C22,"")
D23: =IFERROR(B23/C23,"")
A24: إجمالي التقييم السنوي للعقد | D24: =AVERAGE(D13:D23) -> 0.92857143
A26: الشهر | B26: التحليل الوصفي | E26: الإجراء التصحيحي | K26: المسؤول عن التنفيذ | M26: المدة

Sheet تداول النفايات
A1: جمهورية مصر العربية | I1: Arab Republic of Egypt
A2: الهيئة العامة للرعاية الصحية | I2: General Authority of Health Care
A3: مستشفي شرم الشيخ الدولي | B3: مجمع الفيروز الطبي | I3: AL Fayrouz Medical Complex
A6: مراقبة وتقييم عقد تداول النفايات الخطرة
A7: م | B7: البند | C7: التقييم (ربع سنوي)
C8: 3/2026 | D8: 6/2026 | E8: 9/2026
A9: 1 | B9: يتم طبقا لقرار وزير الصحة 467 لسنة 2020 ووفقا لقانون البيئة رقم 4 لسنة 1994 | C9: 1 | D9: 1 | E9: 1
A10: 2 | B10: الالتزام بمواعيد الاستدعاء حسب المواعيد المقررة بالعقد | C10: 1 | D10: 1 | E10: 1
A11: النسبة الإجمالية | C11: =IFERROR(AVERAGE(C9:C10),"-") -> 1 | D11: =IFERROR(AVERAGE(D9:D10),"-") -> 1 | E11: =IFERROR(AVERAGE(E9:E10),"-") -> 1 | F11: =IFERROR(AVERAGE(F9:F10),"-") -> - | G11: =IFERROR(AVERAGE(G9:G10),"-") -> - | H11: =IFERROR(AVERAGE(H9:H10),"-") -> - | I11: =IFERROR(AVERAGE(I9:I10),"-") -> -

Sheet     Chart
A1: جمهورية مصر العربية | M1: Arab Republic of Egypt
A2: الهيئة العامة للرعاية الصحية | M2: General Authority of Health Care
A3: مجمع الفيروز الطبي | M3: AL Fayrouz Medical Complex
A6: مراقبة وتقييم عقد تداول النفايات
A8: البسط | B8: عدد بنود التقييم المحققة
A9: المقام | B9: إجمالي عدد بنود التقييم (المحددة)
A10: المستهدف | B10: 0.8
A12: الشهر | B12: البسط | C12: المقام | D12: النسبة
A13: 3/2026 | B13: =SUMPRODUCT(--('تداول النفايات'!$C$9:$C$10&""="1")) -> 2 | C13: =SUMPRODUCT(--('تداول النفايات'!$C$9:$C$10&""="1"))+SUMPRODUCT(--('تداول النفايات'!$C$9:$C$10&""="0")) -> 2 | D13: =IFERROR(B13/C13,"") -> 1
A14: 6/2026 | B14: =SUMPRODUCT(--('تداول النفايات'!$D$9:$D$10&""="1")) -> 2 | C14: =SUMPRODUCT(--('تداول النفايات'!$D$9:$D$10&""="1"))+SUMPRODUCT(--('تداول النفايات'!$D$9:$D$10&""="0")) -> 2 | D14: =IFERROR(B14/C14,"") -> 1
A15: 9/2026 | B15: =SUMPRODUCT(--('تداول النفايات'!$E$9:$E$10&""="1")) -> 2 | C15: =SUMPRODUCT(--('تداول النفايات'!$E$9:$E$10&""="1"))+SUMPRODUCT(--('تداول النفايات'!$E$9:$E$10&""="0")) -> 2 | D15: =IFERROR(B15/C15,"") -> 1
D16: =IFERROR(B16/C16,"")
D17: =IFERROR(B17/C17,"")
D18: =IFERROR(B18/C18,"")
D19: =IFERROR(B19/C19,"")
D20: =IFERROR(B20/C20,"")
D21: =IFERROR(B21/C21,"")
D22: =IFERROR(B22/C22,"")
D23: =IFERROR(B23/C23,"")
A24: إجمالي التقييم السنوي للعقد | D24: =AVERAGE(D13:D23) -> 1
A26: الشهر | B26: التحليل الوصفي | E26: الإجراء التصحيحي | K26: المسؤول عن التنفيذ | M26: المدة

Sheet توريد دم
A1: جمهورية مصر العربية | M1: Arab Republic of Egypt
A2: الهيئة العامة للرعاية الصحية | M2: General Authority of Health Care
A3: مجمع الفيروز الطبي | M3: AL Fayrouz Medical Complex
A6: مراقبة وتقييم عقد توريد دم
A7: م | B7: البند | C7: التقييم (ربع سنوي)
C8: 3/2026 | D8: 6/2026 | E8: 9/2026
A9: 1 | B9: توفيره بشكل امن وخالي من أي فيروسات بالطرق المستخدمة بالمركز | C9: 1 | D9: 1 | E9: 1
A10: 2 | B10: تليبة الاحتياجات من الدم ومشتقاته بقدر المتاح | C10: 1 | D10: 1 | E10: 1
A11: 3 | B11: الالتزام ببيع وحدات الدم ومشتقاته بالسعر المتعاقد عليه –المدعم من وزارة الصحة- والاستخدام فى غرضه المشروع | C11: 1 | D11: 1 | E11: 1
A12: النسبة الإجمالية | C12: =IFERROR(AVERAGE(C9:C11),"-") -> 1 | D12: =IFERROR(AVERAGE(D9:D11),"-") -> 1 | E12: =IFERROR(AVERAGE(E9:E11),"-") -> 1 | F12: =IFERROR(AVERAGE(F9:F11),"-") -> - | G12: =IFERROR(AVERAGE(G9:G11),"-") -> - | H12: =IFERROR(AVERAGE(H9:H11),"-") -> - | I12: =IFERROR(AVERAGE(I9:I11),"-") -> - | J12: =IFERROR(AVERAGE(I9:I11),"-") -> - | K12: =IFERROR(AVERAGE(K9:K11),"-") -> - | L12: =IFERROR(AVERAGE(L9:L11),"-") -> - | M12: =IFERROR(AVERAGE(M9:M11),"-") -> -

Sheet     Chart 
A1: جمهورية مصر العربية | M1: Arab Republic of Egypt
A2: الهيئة العامة للرعاية الصحية | M2: General Authority of Health Care
A3: مجمع الفيروز الطبي | M3: AL Fayrouz Medical Complex
A6: مراقبة وتقييم عقد توريد دم
A8: البسط | B8: عدد بنود التقييم المحققة
A9: المقام | B9: إجمالي عدد بنود التقييم (المحددة)
A10: المستهدف | B10: 0.8
A12: الشهر | B12: البسط | C12: المقام | D12: النسبة
A13: 3/2026 | B13: =SUMPRODUCT(--('توريد دم'!$C$9:$C$11&""="1")) -> 3 | C13: =SUMPRODUCT(--('توريد دم'!$C$9:$C$11&""="1"))+SUMPRODUCT(--('توريد دم'!$C$9:$C$11&""="0")) -> 3 | D13: =IFERROR(B13/C13,"") -> 1
A14: 6/2026 | B14: =SUMPRODUCT(--('توريد دم'!$D$9:$D$11&""="1")) -> 3 | C14: =SUMPRODUCT(--('توريد دم'!$D$9:$D$11&""="1"))+SUMPRODUCT(--('توريد دم'!$D$9:$D$11&""="0")) -> 3 | D14: =IFERROR(B14/C14,"") -> 1
A15: 9/2026 | B15: =SUMPRODUCT(--('توريد دم'!$E$9:$E$11&""="1")) -> 3 | C15: =SUMPRODUCT(--('توريد دم'!$E$9:$E$11&""="1"))+SUMPRODUCT(--('توريد دم'!$E$9:$E$11&""="0")) -> 3 | D15: =IFERROR(B15/C15,"") -> 1
D16: =IFERROR(B16/C16,"")
D17: =IFERROR(B17/C17,"")
D18: =IFERROR(B18/C18,"")
D19: =IFERROR(B19/C19,"")
D20: =IFERROR(B20/C20,"")
D21: =IFERROR(B21/C21,"")
D22: =IFERROR(B22/C22,"")
D23: =IFERROR(B23/C23,"")
A24: إجمالي التقييم السنوي للعقد | D24: =AVERAGE(D13:D23) -> 1
A26: الشهر | B26: التحليل الوصفي | E26: الإجراء التصحيحي | K26: المسؤول عن التنفيذ | M26: المدة

Sheet المخلفات الغير طبية
A1: جمهورية مصر العربية | G1: Arab Republic of Egypt
A2: الهيئة العامة للرعاية الصحية | G2: General Authority of Health Care
A3: مستشفي شرم الشيخ الدولي | G3: Sharm International Hospital
A6: مراقبة وتقييم عقد المخلفات غير الطبية
A7: م | B7: البند | C7: التقييم (ربع سنوي)
C8: 6/2022 | D8: 9/2022 | E8: 12/2022 | F8: 3/2023 | G8: 6/2023 | H8: 9/2023 | I8: 12/2023
A9: 1 | B9: الالتزام بكافة التشريعات والقوانين البيئية لتنفيذ عمليات وتشغيل الخدمات لضمان نقل المخلفات الغير طبية | C9: 1 | D9: 1 | E9: 1 | F9: 1 | G9: 1 | H9: 1
A10: 2 | B10: الالتزام بمواعيد نقل النفايات | C10: 1 | D10: 1 | E10: 1 | F10: 1 | G10: 1 | H10: 1
A11: 3 | B11: الالتزام بنقل المخلفات الغير طبية بمعدات وسيارات الوحدة المحلية لمركز ومدينة القنطرة غرب بطريقة سليمة بيئيا وموثوق بها ونقلها للمقلب الرئيسي | C11: 1 | D11: 1 | E11: 1 | F11: 1 | G11: 1 | H11: 1
A12: النسبة الإجمالية | C12: =IFERROR(AVERAGE(C9:C11),"-") -> 1 | D12: =IFERROR(AVERAGE(D9:D11),"-") -> 1 | E12: =IFERROR(AVERAGE(E9:E11),"-") -> 1 | F12: =IFERROR(AVERAGE(F9:F11),"-") -> 1 | G12: =IFERROR(AVERAGE(G9:G11),"-") -> 1 | H12: =IFERROR(AVERAGE(H9:H11),"-") -> 1 | I12: =IFERROR(AVERAGE(I9:I11),"-") -> -

Sheet Chart (9)
A1: جمهورية مصر العربية | M1: Arab Republic of Egypt
A2: الهيئة العامة للرعاية الصحية | M2: General Authority of Health Care
A3: مستشفي شرم الشيخ الدولي | L3: Sharm International Hospital | M3: Ismailia Branch
A6: مراقبة وتقييم عقد المخلفات غير الطبية
A8: البسط | B8: عدد بنود التقييم المحققة
A9: المقام | B9: إجمالي عدد بنود التقييم (المحددة)
A10: المستهدف | B10: 0.8
A12: الشهر | B12: البسط | C12: المقام | D12: النسبة
A13: يونيو 2022 | B13: 3 | C13: 3 | D13: =B13/C13 -> 1
A14: سبتمبر 2022 | B14: 3 | C14: 3 | D14: =B14/C14 -> 1
A15: ديسمبر 2022 | B15: 3 | C15: 3 | D15: =B15/C15 -> 1
A16: مارس 2023 | B16: 3 | C16: 3 | D16: =B16/C16 -> 1
A17: يونيو 2023 | B17: 3 | C17: 3 | D17: =B17/C17 -> 1
A18: سبتمبر 2023 | B18: 3 | C18: 3 | D18: =B18/C18 -> 1
A19: ديسمبر 2023
A20: إجمالي التقييم السنوي للعقد | D20: =AVERAGE(D13:D17) -> 1
A22: الشهر | B22: التحليل الوصفي | E22: الإجراء التصحيحي | K22: المسؤول عن التنفيذ | M22: المدة
A23: يونيو 2022 | B23: تحقيق المؤشر للنسبة المستهدفة | E23: - | K23: - | M23: -
A24: سبتمبر 2022 | B24: تحقيق المؤشر للنسبة المستهدفة | E24: - | K24: - | M24: -
A25: ديسمبر 2022 | B25: تحقيق المؤشر للنسبة المستهدفة | E25: - | K25: - | M25: -
A26: مارس 2023 | B26: تحقيق المؤشر للنسبة المستهدفة | E26: - | K26: - | M26: -
A27: يونيو 2023 | B27: تحقيق المؤشر للنسبة المستهدفة | E27: - | K27: - | M27: -
A28: سبتمبر 2023 | B28: تحقيق المؤشر للنسبة المستهدفة | E28: - | K28: - | M28: -
A29: ديسمبر 2023

Sheet توريد وإعداد الوجبات
A1: جمهورية مصر العربية | M1: Arab Republic of Egypt
A2: الهيئة العامة للرعاية الصحية | M2: General Authority of Health Care
A3: مجمع الفيروز الطبي | M3: AL Fayrouz Medical Complex
A6: مراقبة وتقييم عقد توريد وإعداد الوجبات
A7: م | B7: البند
C8: 3/2026 | D8: 6/2026 | E8: 9/2026
A9: 1 | B9: في حالة استبدال اللحوم والدواجن أو العكس وفقا للقوائم الأسبوعية مع خصم فروق الأسعار | C9: 1 | D9: 1 | E9: 1
A10: 2 | B10: في حالة عدم توريد اة صنف أو رفض اى صنف لعدم مطابقته يتم الشراء من السوق المحلى على حساب الجهة الموردة بجانب العرامة الإدارية وفروق الأسعار على كل صنف مطلوب توريده . | C10: 1 | D10: 1 | E10: 1
A11: 3 | B11: في حالة عدم توريد أي صنف من الوجبات الرئيسية أو البينية وتعذر الشراء يخصم ثمن هذا الصنف من كل وجبة بجانب الغرامة لكل صنف | C11: 1 | D11: 1 | E11: 1
A12: 4 | B12: مخالفة الزى أو عدم نظافته أو عدم الإلتزام بشروط مكافحة العدوى لكل عامل على حدى | C12: 0 | D12: 1 | E12: 1
A13: 5 | B13: مخافة النظافة أو عدم الإلتزام بنظافة الهود أو وجود حشرات بالمطبخ أو الأوفسات | C13: 1 | D13: 1 | E13: 0
A14: 6 | B14: في حالة عدم الألتزام بمواعيد تقديم الوجبات عن المواعيد المقررة | C14: 0 | D14: 0 | E14: 1
A15: 7 | B15: عدم الألتزام بنقل وتقديم الوجبات طبقا لإشتراطات الهيئة القومية لسلامة الغذاء للوحدات والمراكز التابعة للمنشأة | C15: 1 | D15: 1 | E15: 1
A16: 8 | B16: عدم الإلتزام بمواصفات التغليف للوجبات | C16: 1 | D16: 1 | E16: 1
A17: 9 | B17: في حالة نقص العمالة عن العدد المطلوب يوميا ولكل عامل على حدى | C17: 1 | D17: 1 | E17: 1
A18: 10 | B18: في حالة عدم الإلتزام بتخزين الأغذية الجافة عن مدة تكفى 7 أيام لكل صنف على حدى | C18: 1 | D18: 1 | E18: 1
A19: 11 | B19: في حالة عدم الإلتزام بشروط التوريد والتخزين | C19: 1 | D19: 1 | E19: 1
A20: 12 | B20: وجود اى وجبة مقمة مخالفة للأوزان والمقننات وطرق الطهى أو عدم استخدام التوابل يتم خصم ثمن الصنف المخالف | C20: 0 | D20: 1 | E20: 1
... A33: 25 | B33: في حالة عدم توفير أدوات النظافة والمنظفات | C33: 1 | D33: 1 | E33: 1
A34: النسبة الإجمالية | C34: =IFERROR(AVERAGE(C9:C33),"-") -> 0.88 | D34: =IFERROR(AVERAGE(D9:D33),"-") -> 0.92 | E34: =IFERROR(AVERAGE(E9:E33),"-") -> 0.92 | F34: =IFERROR(AVERAGE(F9:F33),"-") -> - | G34: =IFERROR(AVERAGE(G9:G33),"-") -> - | H34: =IFERROR(AVERAGE(H9:H33),"-") -> - | I34: =IFERROR(AVERAGE(I9:I33),"-") -> - | J34: =IFERROR(AVERAGE(J9:J33),"-") -> - | ... M34: =IFERROR(AVERAGE(M9:M33),"-") -> -

Sheet    Chart  
A1: جمهورية مصر العربية | M1: Arab Republic of Egypt
A2: الهيئة العامة للرعاية الصحية | M2: General Authority of Health Care
A3: مجمع الفيروز الطبي | M3: AL Fayrouz Medical Complex
A6: مراقبة وتقييم عقد توريد وإعداد الوجبات
A8: البسط | B8: عدد بنود التقييم المحققة
A9: المقام | B9: إجمالي عدد بنود التقييم (المحددة)
A10: المستهدف | B10: 0.8
A12: الشهر | B12: البسط | C12: المقام | D12: النسبة
A13: 3/2026 | B13: =SUMPRODUCT(--('توريد وإعداد الوجبات'!$C$9:$C$33&""="1")) -> 22 | C13: =SUMPRODUCT(--('توريد وإعداد الوجبات'!$C$9:$C$33&""="1"))+SUMPRODUCT(--('توريد وإعداد الوجبات'!$C$9:$C$33&""="0")) -> 25 | D13: =IFERROR(B13/C13,"") -> 0.88
A14: 6/2026 | B14: =SUMPRODUCT(--('توريد وإعداد الوجبات'!$D$9:$D$33&""="1")) -> 23 | C14: =SUMPRODUCT(--('توريد وإعداد الوجبات'!$D$9:$D$33&""="1"))+SUMPRODUCT(--('توريد وإعداد الوجبات'!$D$9:$D$33&""="0")) -> 25 | D14: =IFERROR(B14/C14,"") -> 0.92
A15: 9/2026 | B15: =SUMPRODUCT(--('توريد وإعداد الوجبات'!$E$9:$E$33&""="1")) -> 23 | C15: =SUMPRODUCT(--('توريد وإعداد الوجبات'!$E$9:$E$33&""="1"))+SUMPRODUCT(--('توريد وإعداد الوجبات'!$E$9:$E$33&""="0")) -> 25 | D15: =IFERROR(B15/C15,"") -> 0.92
D16: =IFERROR(B16/C16,"")
D17: =IFERROR(B17/C17,"")
D18: =IFERROR(B18/C18,"")
D19: =IFERROR(B19/C19,"")
D20: =IFERROR(B20/C20,"")
D21: =IFERROR(B21/C21,"")
D22: =IFERROR(B22/C22,"")
D23: =IFERROR(B23/C23,"")
A24: إجمالي التقييم السنوي للعقد | D24: =AVERAGE(D13:D23) -> 0.90666667
A26: الشهر | B26: التحليل الوصفي | E26: الإجراء التصحيحي | K26: المسؤول عن التنفيذ | M26: المدة

Sheet اجهزة الاشعة المتنقلة
B1: جمهورية مصر العربية | L1: Arab Republic of Egypt
B2: الهيئة العامة للرعاية الصحية | L2: General Authority of Health Care
B3: مستشفي شرم الشيخ الدولي | L3: Sharm International Hospital
A6: مراقبة وتقييم عقد صيانة أجهزة الأشعة المتنقلة
A7: م | B7: البند | C7: التقييم (ربع سنوي)
C8: 6/2022 | D8: 9/2022 | E8: 12/2022 | F8: 3/2023 | G8: 6/2023 | H8: 9/2023 | I8: 12/2023 | J8: 3/2024 | K8: 6/2024 | L8: 12/2023
A9: 1 | B9: اتمام عملية اصلاح الجهاز خلال 24 ساعة من تاريخ الاستجابة للعطل في حالة عدم احتياج الجهاز الي قطع غيار | C9: 1 | D9: 1 | E9: 1 | F9: 1 | G9: 1 | H9: 1 | I9: 1 | J9: 1 | K9: 1 | L9: 1
A10: 2 | B10: اتمام عملية اصلاح الجهاز خلال 48 ساعة من تاريخ الاستجابة للعطل في حالة احتياج الجهاز الي قطع غيار متوفرة بالسوق المحلي | C10: 1 | D10: 1 | E10: 1 | F10: 1 | G10: 1 | H10: 1 | I10: 1 | J10: 1 | K10: 1 | L10: 1
A11: 3 | B11: اتمام عملية اصلاح الجهاز خلال 21 يوم من تاريخ الاستجابة للعطل في حالة احتياج الجهاز الي قطع غيار غير متوفرة بمخازنه و يلزم استيرادها من الخارج و هذا الاستثناء لا يجوز ان يزيد علي مرتين في العام الواحد | C11: 1 | D11: 1 | E11: 1 | F11: 1 | G11: 1 | H11: 1 | I11: 1 | J11: 1 | K11: 1 | L11: 1
A12: 4 | B12: تدريب العاملين و المستخدمين للاجهزة الموجودة بهذا العقد | C12: 1 | D12: 1 | E12: 1 | F12: 1 | G12: 1 | H12: 1 | I12: 1 | J12: 1 | K12: 1 | L12: 1
A13: 5 | B13: ضمان معدل عمل الاجهزة موضوع التعاقد (ضمان وجود الاجهزة في الخدمة) لا يقل عن 95 % من الايام المتفق عليها و هي 300 يوم سنويا | C13: 1 | D13: 1 | E13: 1 | F13: 1 | G13: 1 | H13: 1 | I13: 1 | J13: 1 | K13: 1 | L13: 1
A14: النسبة الإجمالية | C14: =IFERROR(AVERAGE(C9:C13),"-") -> 1 | D14: =IFERROR(AVERAGE(D9:D13),"-") -> 1 | E14: =IFERROR(AVERAGE(E9:E13),"-") -> 1 | F14: =IFERROR(AVERAGE(F9:F13),"-") -> 1 | G14: =IFERROR(AVERAGE(G9:G13),"-") -> 1 | H14: =IFERROR(AVERAGE(H9:H13),"-") -> 1 | I14: =IFERROR(AVERAGE(I9:I13),"-") -> 1 | J14: =IFERROR(AVERAGE(J9:J13),"-") -> 1 | ... L14: =IFERROR(AVERAGE(L9:L13),"-") -> 1

Sheet عقد الصيانة
A1: جمهورية مصر العربية | L1: Arab Republic of Egypt
A2: الهيئة العامة للرعاية الصحية | L2: General Authority of Health Care
A3: مجمع الفيروز الطبي | M3: AL Fayrouz Medical Complex
A6: مراقبة وتقييم عقد صيانة المرافق
A7: م | B7: البند | C7: التقييم (ربع سنوي)
C8: 3/2026 | D8: 6/2026 | E8: 9/2026
A9: 1 | B9: غياب مهندس يوم عمل | C9: 1 | D9: 1 | E9: 0
A10: 2 | B10: غياب فنى/مشرف | C10: 0 | D10: 0 | E10: 0
A11: 3 | B11: عدم الالتزام بالزى المعتمد | C11: 1 | D11: 1 | E11: 1
A12: 4 | B12: عدم التزام فرد او مجموعة عمل بالتعليمات والتعليمات العامة | C12: 1 | D12: 1 | E12: 1
A13: 5 | B13: عدم تنفيذ الصيانة للمعدات الآتية :- الشيلررات ونظام VRF وأنظمة DX وحدات مناولة الهواء - مولدات الطاقة الكهربائية - الغلابة المركزية - مراوح سحب الدخان - معدات نظام الغاز | C13: 1 | D13: 1 | E13: 1
A14: 6 | B14: عدم تنفيذ الصيانة الدورية المخططة للمعدات الآتية :- التكييفات المنفصلة وأوكونسليد أو FCU - معدات تهوية منشأة - الطلمبات بانواعها - أجهزة UPS - معدات المغسلة والمطبخ - لوحات الكهرباء - معدات الغاز الطبية الفرعية - معدات التيار الخفيف -معدات مكافحة الحريق | C14: 1 | D14: 1 | E14: 1
A15: 7 | B15: عطل مصعد | C15: 1 | D15: 1 | E15: 1
A16: 8 | B16: عطل مولد قوى | C16: 1 | D16: 0 | E16: 0
A17: 9 | B17: عطل معدة بمنظومة الغازات الطبية | C17: 1 | D17: 1 | E17: 1
A18: 10 | B18: عطل كلى بنظام تكييف مركزى - الشيلارات ونظام VRF - أنظمة DX - خروج كلى عن الخدمة | C18: 1 | D18: 1 | E18: 1
A19: 11 | B19: عطل جزئى بنظام تكييف مركزى - الشيلارات ونظام VRF - أنظمة DX | C19: 1 | D19: 1 | E19: 1
A20: 12 | B20: عطل وحدة تكييف منفصلة و أوكونسيك أو FCU | C20: 1 | D20: 1 | E20: 1
... A35: 27 | B35: عدم تطهير الخزانات وتقديم العينة | C35: 1 | D35: 1 | E35: 1
A36: النسبة الإجمالية | C36: =AVERAGE(C9:C35) -> 0.92592593 | D36: =IFERROR(AVERAGE(D9:D35),"-") -> 0.88888889 | E36: =IFERROR(AVERAGE(E9:E35),"-") -> 0.85185185 | F36: =IFERROR(AVERAGE(F9:F35),"-") -> - | G36: =IFERROR(AVERAGE(G9:G35),"-") -> - | H36: =IFERROR(AVERAGE(H9:H35),"-") -> - | I36: =IFERROR(AVERAGE(I9:I35),"-") -> - | J36: =IFERROR(AVERAGE(J9:J35),"-") -> - | K36: =IFERROR(AVERAGE(K9:K35),"-") -> - | L36: =IFERROR(AVERAGE(L9:L35),"-") -> -

Sheet    Chart   
A1: جمهورية مصر العربية | M1: Arab Republic of Egypt
A2: الهيئة العامة للرعاية الصحية | M2: General Authority of Health Care
A3: مجمع الفيروز الطبي | M3: AL Fayrouz Medical Complex
A6: مراقبة وتقييم عقد صيانة المرافق
A8: البسط | B8: عدد بنود التقييم المحققة
A9: المقام | B9: إجمالي عدد بنود التقييم (المحددة)
A10: المستهدف | B10: 0.8
A12: الشهر | B12: البسط | C12: المقام | D12: النسبة
A13: 3/2026 | B13: =SUMPRODUCT(--('عقد الصيانة'!$C$9:$C$35&""="1")) -> 25 | C13: =SUMPRODUCT(--('عقد الصيانة'!$C$9:$C$35&""="1"))+SUMPRODUCT(--('عقد الصيانة'!$C$9:$C$35&""="0")) -> 27 | D13: =IFERROR(B13/C13,"") -> 0.92592593
A14: 6/2026 | B14: =SUMPRODUCT(--('عقد الصيانة'!$D$9:$D$35&""="1")) -> 24 | C14: =SUMPRODUCT(--('عقد الصيانة'!$D$9:$D$35&""="1"))+SUMPRODUCT(--('عقد الصيانة'!$D$9:$D$35&""="0")) -> 27 | D14: =IFERROR(B14/C14,"") -> 0.88888889
A15: 9/2026 | B15: =SUMPRODUCT(--('عقد الصيانة'!$E$9:$E$35&""="1")) -> 23 | C15: =SUMPRODUCT(--('عقد الصيانة'!$E$9:$E$35&""="1"))+SUMPRODUCT(--('عقد الصيانة'!$E$9:$E$35&""="0")) -> 27 | D15: =IFERROR(B15/C15,"") -> 0.85185185
D16: =IFERROR(B16/C16,"")
D17: =IFERROR(B17/C17,"")
D18: =IFERROR(B18/C18,"")
D19: =IFERROR(B19/C19,"")
D20: =IFERROR(B20/C20,"")
D21: =IFERROR(B21/C21,"")
D22: =IFERROR(B22/C22,"")
A23: إجمالي التقييم السنوي للعقد | D23: =AVERAGE(D13:D22) -> 0.88888889
A25: الشهر | B25: التحليل الوصفي | E25: الإجراء التصحيحي | K25: المسؤول عن التنفيذ | M25: المدة
A26: يناير | B26: عدم الإلتزام بالأعداد والتخصصات | E26: خصم التقييم والتنبيه على الشركة بضرورة إستكمال الأعداد والتخصصات | K26: مدير التشغيل | M26: شهر
A27: مارس | B27: تأخر تفعيل البرامج المخصصة لإدارة الصيانات | E27: خصم بند البرنامج مع التنبيه بضرورة الإسراع في تفعيل البرنامج | K27: مدير التشغيل | M27: شهرين

Sheet مكافحة القوارض
A1: جمهورية مصر العربية | M1: Arab Republic of Egypt
A2: الهيئة العامة للرعاية الصحية | M2: General Authority of Health Care
A3: مجمع الفيروز الطبي | M3: AL Fayrouz Medical Complex
A6: مراقبة وتقييم عقد مكافحة القوارض و الحشرات
A7: م | B7: البند | C7: التقييم (ربع سنوي)
C8: 3/2026 | D8: 6/2026 | E8: 46266
A9: 1 | B9: التزام الشركة بمواعيد الزيارات المحددة | C9: 1 | D9: 1 | E9: 1
A10: 2 | B10: توفير المواد المصرح بها من وزارة الصحة | C10: 1 | D10: 1 | E10: 1
A11: 3 | B11: استخدام الأدوات الحديثة لمكافحة الحشرات | C11: 1 | D11: 1 | E11: 1
A12: 4 | B12: الالتزام بتقديم التقارير في الوقت المحدد | C12: 1 | D12: 1 | E12: 1
A13: 5 | B13: متابعة مصايد الذباب و القوارض | C13: 1 | D13: 1 | E13: 1
A14: النسبة الإجمالية | C14: =IFERROR(AVERAGE(C9:C13),"-") -> 1 | D14: =IFERROR(AVERAGE(D9:D13),"-") -> 1 | E14: =IFERROR(AVERAGE(E9:E13),"-") -> 1 | F14: =IFERROR(AVERAGE(F9:F13),"-") -> - | G14: =IFERROR(AVERAGE(G9:G13),"-") -> - | H14: =IFERROR(AVERAGE(H9:H13),"-") -> - | I14: =IFERROR(AVERAGE(I9:I13),"-") -> - | J14: =IFERROR(AVERAGE(J9:J13),"-") -> - | ... M14: =IFERROR(AVERAGE(M9:M13),"-") -> -

Sheet      Chart     
A1: جمهورية مصر العربية | Q1: Arab Republic of Egypt
A2: الهيئة العامة للرعاية الصحية | Q2: General Authority of Health Care
A3: مجمع الفيروز الطبي | M3: AL Fayrouz Medical Complex
A6: مراقبة وتقييم عقد مكافحة القوارض و الحشرات
A8: البسط | B8: عدد بنود التقييم المحققة
A9: المقام | B9: إجمالي عدد بنود التقييم (المحددة)
A10: المستهدف | B10: 0.8
A12: الشهر | B12: البسط | C12: المقام | D12: النسبة
A13: 3/2026 | B13: =SUMPRODUCT(--('مكافحة القوارض'!$C$9:$C$13&""="1")) -> 5 | C13: =SUMPRODUCT(--('مكافحة القوارض'!$C$9:$C$13&""="1"))+SUMPRODUCT(--('مكافحة القوارض'!$C$9:$C$13&""="0")) -> 5 | D13: =IFERROR(B13/C13,"") -> 1
A14: 6/2026 | B14: =SUMPRODUCT(--('مكافحة القوارض'!$D$9:$D$13&""="1")) -> 5 | C14: =SUMPRODUCT(--('مكافحة القوارض'!$D$9:$D$13&""="1"))+SUMPRODUCT(--('مكافحة القوارض'!$D$9:$D$13&""="0")) -> 5 | D14: =IFERROR(B14/C14,"") -> 1
A15: 9/2026 | B15: =SUMPRODUCT(--('مكافحة القوارض'!$E$9:$E$13&""="1")) -> 5 | C15: =SUMPRODUCT(--('مكافحة القوارض'!$E$9:$E$13&""="1"))+SUMPRODUCT(--('مكافحة القوارض'!$E$9:$E$13&""="0")) -> 5 | D15: =IFERROR(B15/C15,"") -> 1
D16: =IFERROR(B16/C16,"")
D17: =IFERROR(B17/C17,"")
D18: =IFERROR(B18/C18,"")
D19: =IFERROR(B19/C19,"")
D20: =IFERROR(B20/C20,"")
D21: =IFERROR(B21/C21,"")
D22: =IFERROR(B22/C22,"")
D23: =IFERROR(B23/C23,"")
A24: إجمالي التقييم السنوي للعقد | D24: =AVERAGE(D13:D23) -> 1
A26: الشهر | B26: التحليل الوصفي | E26: الإجراء التصحيحي | K26: المسؤول عن التنفيذ | M26: المدة

Sheet معالجة مياه الكلي
A1: جمهورية مصر العربية | M1: Arab Republic of Egypt
A2: الهيئة العامة للرعاية الصحية | M2: General Authority of Health Care
A3: مجمع الفيروز الطبي | M3: AL Fayrouz Medical Complex
A6: مراقبة وتقييم عقد معالجة مياة وحدة الكلي
A7: م | B7: البند | C7: التقييم (ربع سنوي)
C8: 3/2026 | D8: 6/2026 | E8: 9/2026 | F8: 12/2026
A9: 1 | B9: التزام الشركة بمواعيد زيارات الصيانة الوقائية بواقع زيارة واحدة شهر | C9: 1 | D9: 1 | E9: 1
A10: 2 | B10: تدريب العاملين و المستخدمين للاجهزة الموجودة بهذا العقد | C10: 1 | D10: 1 | E10: 1
A11: 3 | B11: اتمام عملية استيراد قطع الغيار الاصلية و الجديدة الغير متوفرة محليا خلا ل 4 يوم من تاريخ تحديد القطع التالفة | C11: 1 | D11: 1 | E11: 1
A12: 4 | B12: اتمام عملية اصلاح الجهاز خلال 24 ساعة من تاريخ الاستجابة للعطل في حالة عدم احتياج الجهاز الي قطع غيار | C12: 1 | D12: 1 | E12: 1
A13: 5 | B13: اتمام عملية اصلاح الجهاز خلال 48 ساعة من تاريخ الاستجابة للعطل في حالة احتياج الجهاز الي قطع غيار متوفرة بالسوق المحلي | C13: 1 | D13: 1 | E13: 1
A14: النسبة الإجمالية | C14: =AVERAGE(C9:C13) -> 1 | D14: 1 | E14: 1 | F14: =AVERAGE(F9:F13) -> #DIV/0! | G14: =IFERROR(AVERAGE(G9:G13),"-") -> - | H14: =IFERROR(AVERAGE(H9:H13),"-") -> - | I14: =IFERROR(AVERAGE(I9:I13),"-") -> - | J14: =IFERROR(AVERAGE(J9:J13),"-") -> - | K14: =IFERROR(AVERAGE(K9:K13),"-") -> - | L14: =IFERROR(AVERAGE(L9:L13),"-") -> - | M14: =IFERROR(AVERAGE(M9:M13),"-") -> -

Sheet صيانة وقائية و اصلاحية ميديكال
B1: جمهورية مصر العربية | G1: Arab Republic of Egypt
B2: الهيئة العامة للرعاية الصحية | G2: General Authority of Health Care
B3: مستشفي شرم الشيخ الدولي | G3: Sharm International Hospital
A6: مراقبة وتقييم عقد صيانة طبية وقائية و اصلاحية ميديكال
A7: م | B7: البند | C7: التقييم (ربع سنوي)
C8: 6/2022 | D8: 9/2022 | E8: 12/2022 | F8: 3/2023 | G8: 6/2023 | H8: 9/2023 | I8: 12/2023
A9: 1 | B9: اتمام عملية اصلاح الجهاز خلال 24 ساعة من تاريخ الاستجابة للعطل في حالة عدم احتياج الجهاز الي قطع غيار | C9: 1 | D9: 1 | E9: 1 | F9: 1 | G9: 1 | H9: 1
A10: 2 | B10: اتمام عملية اصلاح الجهاز خلال 48 ساعة من تاريخ الاستجابة للعطل في حالة احتياج الجهاز الي قطع غيار متوفرة بالسوق المحلي | C10: 1 | D10: 1 | E10: 1 | F10: 1 | G10: 1 | H10: 1
A11: 3 | B11: اتمام عملية اصلاح الجهاز خلال 21 يوم من تاريخ الاستجابة للعطل في حالة احتياج الجهاز الي قطع غيار غير متوفرة بمخازنه و يلزم استيرادها من الخارج و هذا الاستثناء لا يجوز ان يزيد علي مرتين في العام الواحد | C11: 1 | D11: 1 | E11: 1 | F11: 1 | G11: 1 | H11: 1
A12: 4 | B12: تدريب العاملين و المستخدمين للاجهزة الموجودة بهذا العقد | C12: 1 | D12: 1 | E12: 1 | F12: 1 | G12: 1 | H12: 1
A13: 5 | B13: ضمان معدل عمل الاجهزة موضوع التعاقد (ضمان وجود الاجهزة في الخدمة) لا يقل عن 95 % من الايام المتفق عليها و هي 300 يوم سنويا | C13: 1 | D13: 1 | E13: 1 | F13: 1 | G13: 1 | H13: 1
A14: النسبة الإجمالية | C14: =IFERROR(AVERAGE(C9:C13),"-") -> 1 | D14: =IFERROR(AVERAGE(D9:D13),"-") -> 1 | E14: =IFERROR(AVERAGE(E9:E13),"-") -> 1 | F14: =IFERROR(AVERAGE(F9:F13),"-") -> 1 | G14: =IFERROR(AVERAGE(G9:G13),"-") -> 1 | H14: =IFERROR(AVERAGE(H9:H13),"-") -> 1 | I14: =IFERROR(AVERAGE(I9:I13),"-") -> -

Sheet Chart (13)
B1: جمهورية مصر العربية | M1: Arab Republic of Egypt
B2: الهيئة العامة للرعاية الصحية | M2: General Authority of Health Care
B3: مستشفي شرم الشيخ الدولي | M3: Sharm International Hospital
A6: مراقبة وتقييم عقد صيانة وقائية و اصلاحية
A8: البسط | B8: عدد بنود التقييم المحققة
A9: المقام | B9: إجمالي عدد بنود التقييم (المحددة)
A10: المستهدف | B10: 0.8
A12: الشهر | B12: البسط | C12: المقام | D12: النسبة
A13: يونيو 2022 | B13: 5 | C13: 5 | D13: =B13/C13 -> 1
A14: سبتمبر 2022 | B14: 5 | C14: 5 | D14: =AVERAGE(B14/C14) -> 1
A15: ديسمبر 2022 | B15: 5 | C15: 5 | D15: =AVERAGE(B15/C15) -> 1
A16: مارس 2023 | B16: 5 | C16: 5 | D16: =AVERAGE(B16/C16) -> 1
A17: يونيو 2023 | B17: 5 | C17: 5 | D17: =B17/C17 -> 1
A18: سبتمبر 2023 | B18: 5 | C18: 5 | D18: 1
A19: ديسمبر 2023
A20: إجمالي التقييم السنوي للعقد | D20: =AVERAGE(D13:D19) -> 1
A22: الشهر | B22: التحليل الوصفي | E22: الإجراء التصحيحي | K22: المسؤول عن التنفيذ | M22: المدة
A23: يونيو 2022 | B23: تحقيق المؤشر للنسبة المستهدفة | E23: - | K23: - | M23: -
A24: سبتمبر 2022 | B24: تحقيق المؤشر للنسبة المستهدفة | E24: - | K24: - | M24: -
A25: ديسمبر 2022 | B25: تحقيق المؤشر للنسبة المستهدفة | E25: - | K25: - | M25: -
A26: مارس 2023 | B26: تحقيق المؤشر للنسبة المستهدفة | E26: - | K26: - | M26: -
A27: يونيو 2023 | B27: تحقيق المؤشر للنسبة المستهدفة | E27: - | K27: - | M27: -
A28: سبتمبر 2023 | B28: تحقيق المؤشر للنسبة المستهدفة | E28: - | K28: - | M28: -
A29: ديسمبر 2023

Sheet       Chart    
A1: جمهورية مصر العربية | Q1: Arab Republic of Egypt
A2: الهيئة العامة للرعاية الصحية | Q2: General Authority of Health Care
A3: مجمع الفيروز الطبي | M3: AL Fayrouz Medical Complex
A6: مراقبة وتقييم عقد معالجة مياة وحدة الكلي
A8: البسط | B8: عدد بنود التقييم المحققة
A9: المقام | B9: إجمالي عدد بنود التقييم (المحددة)
A10: المستهدف | B10: 0.8
A12: الشهر | B12: البسط | C12: المقام | D12: النسبة
A13: 3/2026 | B13: =SUMPRODUCT(--('معالجة مياه الكلي'!$C$9:$C$13&""="1")) -> 5 | C13: =SUMPRODUCT(--('معالجة مياه الكلي'!$C$9:$C$13&""="1"))+SUMPRODUCT(--('معالجة مياه الكلي'!$C$9:$C$13&""="0")) -> 5 | D13: =IFERROR(B13/C13,"") -> 1
A14: 6/2026 | B14: =SUMPRODUCT(--('معالجة مياه الكلي'!$D$9:$D$13&""="1")) -> 5 | C14: =SUMPRODUCT(--('معالجة مياه الكلي'!$D$9:$D$13&""="1"))+SUMPRODUCT(--('معالجة مياه الكلي'!$D$9:$D$13&""="0")) -> 5 | D14: =IFERROR(B14/C14,"") -> 1
A15: 9/2026 | B15: =SUMPRODUCT(--('معالجة مياه الكلي'!$E$9:$E$13&""="1")) -> 5 | C15: =SUMPRODUCT(--('معالجة مياه الكلي'!$E$9:$E$13&""="1"))+SUMPRODUCT(--('معالجة مياه الكلي'!$E$9:$E$13&""="0")) -> 5 | D15: =IFERROR(B15/C15,"") -> 1
D16: =IFERROR(B16/C16,"")
D17: =IFERROR(B17/C17,"")
D18: =IFERROR(B18/C18,"")
D19: =IFERROR(B19/C19,"")
D20: =IFERROR(B20/C20,"")
D21: =IFERROR(B21/C21,"")
D22: =IFERROR(B22/C22,"")
D23: =IFERROR(B23/C23,"")
A24: إجمالي التقييم السنوي للعقد | D24: =AVERAGE(D13:D23) -> 1
A26: الشهر | B26: التحليل الوصفي | E26: الإجراء التصحيحي | K26: المسؤول عن التنفيذ | M26: المدة

Sheet  جهاز الرنين
B1: جمهورية مصر العربية | M1: Arab Republic of Egypt
B2: الهيئة العامة للرعاية الصحية | M2: General Authority of Health Care
B3: مجمع الفيروز الطبي | M3: AL Fayrouz Medical Complex
A6: مراقبة وتقييم عقد جهاز الرنين
A7: م | B7: البند | C7: التقييم (ربع سنوي)
C8: 3/2026 | D8: 6/2026 | E8: 9/2026 | F8: 12/2026
A9: 1 | B9: اتمام عملية اصلاح الجهاز خلال 24 ساعة من تاريخ الاستجابة للعطل في حالة عدم احتياج الجهاز الي قطع غيار | C9: 1 | D9: 1 | E9: 1
A10: 2 | B10: اتمام عملية اصلاح الجهاز خلال 48 ساعة من تاريخ الاستجابة للعطل في حالة احتياج الجهاز الي قطع غيار متوفرة بالسوق المحلي | C10: 1 | D10: 1 | E10: 1
A11: 3 | B11: اتمام عملية اصلاح الجهاز خلال 21 يوم من تاريخ تشخيص العطل في حالة احتياج الجهاز الي قطع غيار غير متوفرة بمخازنه و يلزم استيرادها من الخارج و هذا الاستثناء لا يجوز ان يزيد علي مرتين في العام الواحد | C11: 1 | D11: 1 | E11: 1
A12: 4 | B12: تدريب العاملين و المستخدمين للاجهزة الموجودة بهذا العقد | C12: 1 | D12: 1 | E12: 1
A13: 5 | B13: ضمان معدل عمل الاجهزة موضوع التعاقد (ضمان وجود الاجهزة في الخدمة) لا يقل عن 95 % من الايام المتفق عليها و هي 300 يوم سنويا | C13: 1 | D13: 1 | E13: 1
A14: النسبة الإجمالية | C14: =AVERAGE(C9:C13) -> 1 | D14: 1 | E14: 1 | F14: =AVERAGE(F9:F13) -> #DIV/0! | G14: =IFERROR(AVERAGE(G9:G13),"-") -> - | H14: =IFERROR(AVERAGE(H9:H13),"-") -> - | I14: =IFERROR(AVERAGE(I9:I13),"-") -> - | J14: =IFERROR(AVERAGE(J9:J13),"-") -> - | K14: =IFERROR(AVERAGE(K9:K13),"-") -> - | L14: =AVERAGE(L9:L13) -> #DIV/0! | M14: =AVERAGE(M9:M13) -> #DIV/0!

Sheet    Chart 
A1: جمهورية مصر العربية | M1: Arab Republic of Egypt
A2: الهيئة العامة للرعاية الصحية | M2: General Authority of Health Care
A3: مجمع الفيروز الطبي | M3: AL Fayrouz Medical Complex
A6: مراقبة وتقييم عقد جهاز الرنين
A8: البسط | B8: عدد بنود التقييم المحققة
A9: المقام | B9: إجمالي عدد بنود التقييم (المحددة)
A10: المستهدف | B10: 0.8
A12: الشهر | B12: البسط | C12: المقام | D12: النسبة
A13: 3/2026 | B13: =SUMPRODUCT(--(' جهاز الرنين'!$C$9:$C$13&""="1")) -> 5 | C13: =SUMPRODUCT(--(' جهاز الرنين'!$C$9:$C$13&""="1"))+SUMPRODUCT(--(' جهاز الرنين'!$C$9:$C$13&""="0")) -> 5 | D13: =IFERROR(B13/C13,"") -> 1
A14: 6/2026 | B14: =SUMPRODUCT(--(' جهاز الرنين'!$D$9:$D$13&""="1")) -> 5 | C14: =SUMPRODUCT(--(' جهاز الرنين'!$D$9:$D$13&""="1"))+SUMPRODUCT(--(' جهاز الرنين'!$D$9:$D$13&""="0")) -> 5 | D14: =IFERROR(B14/C14,"") -> 1
A15: 9/2026 | B15: =SUMPRODUCT(--(' جهاز الرنين'!$E$9:$E$13&""="1")) -> 5 | C15: =SUMPRODUCT(--(' جهاز الرنين'!$E$9:$E$13&""="1"))+SUMPRODUCT(--(' جهاز الرنين'!$E$9:$E$13&""="0")) -> 5 | D15: =IFERROR(B15/C15,"") -> 1
D16: =IFERROR(B16/C16,"")
D17: =IFERROR(B17/C17,"")
D18: =IFERROR(B18/C18,"")
D19: =IFERROR(B19/C19,"")
D20: =IFERROR(B20/C20,"")
D21: =IFERROR(B21/C21,"")
D22: =IFERROR(B22/C22,"")
D23: =IFERROR(B23/C23,"")
A24: إجمالي التقييم السنوي للعقد | D24: =AVERAGE(D13:D23) -> 1
A26: الشهر | B26: التحليل الوصفي | E26: الإجراء التصحيحي | K26: المسؤول عن التنفيذ | M26: المدة

Sheet صيانة اشعه عاديه
A1: جمهورية مصر العربية | M1: Arab Republic of Egypt
A2: الهيئة العامة للرعاية الصحية | M2: General Authority of Health Care
A3: مجمع الفيروز الطبي | M3: AL Fayrouz Medical Complex
A6: مراقبة وتقييم عقد صيانة اشعه عادية
A7: م | B7: البند | C7: التقييم (ربع سنوي)
C8: 3/2026 | D8: 6/2026 | E8: 9/2026 | F8: 12/2026
A9: 1 | B9: التزام الشركة بمواعيد زيارات الصيانة الوقائية بواقع زيارة واحدة كل ثلاثة اشهر | C9: 1 | D9: 1 | E9: 1
A10: 2 | B10: استجابة الشركة في حالة ابلاغ المستشفي عن عطل بارسال مهندس الصيانة لال 48 ساعة من ابلاغ العطل علي ان تكون طلبات الاصلاح بدون حد أقصي | C10: 1 | D10: 1 | E10: 1
A11: 3 | B11: اتمام عملية استيراد قطع الغيار الاصلية و الجديدة الغير متوفرة محليا خلال 4 يوم من تاريخ تحديد القطع التالفة | C11: 1 | D11: 1 | E11: 1
A12: 4 | B12: تدريب العاملين و المستخدمين للاجهزة الموجودة بهذا العقد | C12: 1 | D12: 1 | E12: 1
A13: 5 | B13: تقديم الشركة بعد كل زيارة وقائية و اصلاحية تقريرا مفصلا عن ما تم من اعمال | C13: 1 | D13: 1 | E13: 1
A14: النسبة الإجمالية | C14: =AVERAGE(C9:C13) -> 1 | D14: 1 | E14: 1 | F14: =AVERAGE(F9:F13) -> #DIV/0! | G14: =IFERROR(AVERAGE(G9:G13),"-") -> - | H14: =IFERROR(AVERAGE(H9:H13),"-") -> - | I14: =AVERAGE(I9:I13) -> #DIV/0! | J14: =AVERAGE(J9:J13) -> #DIV/0! | K14: =AVERAGE(K9:K13) -> #DIV/0! | L14: =IFERROR(AVERAGE(L9:L13),"-") -> - | M14: =IFERROR(AVERAGE(M9:M13),"-") -> -

Sheet    Chart
A1: جمهورية مصر العربية | M1: Arab Republic of Egypt
A2: الهيئة العامة للرعاية الصحية | M2: General Authority of Health Care
A3: مجمع الفيروز الطبي | M3: AL Fayrouz Medical Complex
A6: مراقبة و تقييم عقد صيانة اشعه عادية
A8: البسط | B8: عدد بنود التقييم المحققة
A9: المقام | B9: إجمالي عدد بنود التقييم (المحددة)
A10: المستهدف | B10: 0.8
A12: الشهر | B12: البسط | C12: المقام | D12: النسبة
A13: 3/2026 | B13: =SUMPRODUCT(--('صيانة اشعه عاديه'!$C$9:$C$13&""="1")) -> 5 | C13: =SUMPRODUCT(--('صيانة اشعه عاديه'!$C$9:$C$13&""="1"))+SUMPRODUCT(--('صيانة اشعه عاديه'!$C$9:$C$13&""="0")) -> 5 | D13: =IFERROR(B13/C13,"") -> 1
A14: 6/2026 | B14: =SUMPRODUCT(--('صيانة اشعه عاديه'!$D$9:$D$13&""="1")) -> 5 | C14: =SUMPRODUCT(--('صيانة اشعه عاديه'!$D$9:$D$13&""="1"))+SUMPRODUCT(--('صيانة اشعه عاديه'!$D$9:$D$13&""="0")) -> 5 | D14: =IFERROR(B14/C14,"") -> 1
A15: 9/2026 | B15: =SUMPRODUCT(--('صيانة اشعه عاديه'!$E$9:$E$13&""="1")) -> 5 | C15: =SUMPRODUCT(--('صيانة اشعه عاديه'!$E$9:$E$13&""="1"))+SUMPRODUCT(--('صيانة اشعه عاديه'!$E$9:$E$13&""="0")) -> 5 | D15: =IFERROR(B15/C15,"") -> 1
D16: =IFERROR(B16/C16,"")
D17: =IFERROR(B17/C17,"")
D18: =IFERROR(B18/C18,"")
D19: =IFERROR(B19/C19,"")
D20: =IFERROR(B20/C20,"")
D21: =IFERROR(B21/C21,"")
D22: =IFERROR(B22/C22,"")
D23: =IFERROR(B23/C23,"")
A24: إجمالي التقييم السنوي للعقد | D24: =AVERAGE(D13:D23) -> 1
A26: الشهر | B26: التحليل الوصفي | E26: الإجراء التصحيحي | K26: المسؤول عن التنفيذ | M26: المدة

Sheet جهاز المقطعية
A1: جمهورية مصر العربية | M1: Arab Republic of Egypt
A2: الهيئة العامة للرعاية الصحية | M2: General Authority of Health Care
A3: مجمع الفيروز الطبي | M3: AL Fayrouz Medical Complex
A6: مراقبة وتقييم عقد صيانة جهاز الاشعة المقطعية
A7: م | B7: البند | C7: التقييم (ربع سنوي)
C8: مارس | D8: يونيه | E8: سبتمبر
A9: 1 | B9: التزام الشركة بمواعيد زيارات الصيانة الوقائية بواقع زيارة واحدة كل ثلاثة اشهر | C9: 1 | D9: 1 | E9: 1
A10: 2 | B10: استجابة الشركة في حالة ابلاغ المستشفي عن عطل بارسال مهندس الصيانة لال 48 ساعة من ابلاغ العطل علي ان تكون طلبات الاصلاح بدون حد أقصي | C10: 1 | D10: 1 | E10: 1
A11: 3 | B11: اتمام عملية استيراد قطع الغيار الاصلية و الجديدة الغير متوفرة محليا خلال 4 يوم من تاريخ تحديد القطع التالفة | C11: 1 | D11: 1 | E11: 1
A12: 4 | B12: تدريب العاملين و المستخدمين للاجهزة الموجودة بهذا العقد | C12: 1 | D12: 1 | E12: 1
A13: 5 | B13: تقديم الشركة بعد كل زيارة وقائية و اصلاحية تقريرا مفصلا عن ما تم من اعمال | C13: 1 | D13: 1 | E13: 1
A14: النسبة الإجمالية | C14: 1 | D14: =AVERAGE(D9:D13) -> 1 | E14: =AVERAGE(E9:E13) -> 1 | F14: =AVERAGE(F9:F13) -> #DIV/0! | G14: =IFERROR(AVERAGE(G9:G13),"-") -> - | H14: =IFERROR(AVERAGE(H9:H13),"-") -> - | I14: =AVERAGE(I9:I13) -> #DIV/0! | J14: =AVERAGE(J9:J13) -> #DIV/0! | K14: =AVERAGE(K9:K13) -> #DIV/0! | L14: =IFERROR(AVERAGE(L9:L13),"-") -> - | M14: =IFERROR(AVERAGE(M9:M13),"-") -> -

Sheet   Chart
A1: جمهورية مصر العربية | M1: Arab Republic of Egypt
A2: الهيئة العامة للرعاية الصحية | M2: General Authority of Health Care
A3: مجمع الفيروز الطبي | M3: AL Fayrouz Medical Complex
A6: مراقبة وتقييم عقد صيانة جهاز جهاز الاشعة المقطعية
A8: البسط | B8: عدد بنود التقييم المحققة
A9: المقام | B9: إجمالي عدد بنود التقييم (المحددة)
A10: المستهدف | B10: 0.8
A12: الشهر | B12: البسط | C12: المقام | D12: النسبة
A13: 3/2026 | B13: =SUMPRODUCT(--('جهاز المقطعية'!$C$9:$C$13&""="1")) -> 5 | C13: =SUMPRODUCT(--('جهاز المقطعية'!$C$9:$C$13&""="1"))+SUMPRODUCT(--('جهاز المقطعية'!$C$9:$C$13&""="0")) -> 5 | D13: =IFERROR(B13/C13,"") -> 1
A14: 6/2026 | B14: =SUMPRODUCT(--('جهاز المقطعية'!$D$9:$D$13&""="1")) -> 5 | C14: =SUMPRODUCT(--('جهاز المقطعية'!$D$9:$D$13&""="1"))+SUMPRODUCT(--('جهاز المقطعية'!$D$9:$D$13&""="0")) -> 5 | D14: =IFERROR(B14/C14,"") -> 1
A15: 9/2026 | B15: =SUMPRODUCT(--('جهاز المقطعية'!$E$9:$E$13&""="1")) -> 5 | C15: =SUMPRODUCT(--('جهاز المقطعية'!$E$9:$E$13&""="1"))+SUMPRODUCT(--('جهاز المقطعية'!$E$9:$E$13&""="0")) -> 5 | D15: =IFERROR(B15/C15,"") -> 1
D16: =IFERROR(B16/C16,"")
D17: =IFERROR(B17/C17,"")
D18: =IFERROR(B18/C18,"")
D19: =IFERROR(B19/C19,"")
D20: =IFERROR(B20/C20,"")
D21: =IFERROR(B21/C21,"")
D22: =IFERROR(B22/C22,"")
D23: =IFERROR(B23/C23,"")
A24: إجمالي التقييم السنوي للعقد | D24: =AVERAGE(D13:D23) -> 1
A26: الشهر | B26: التحليل الوصفي | E26: الإجراء التصحيحي | K26: المسؤول عن التنفيذ | M26: المدة

Sheet الكلي الصناعي
A1: جمهورية مصر العربية | M1: Arab Republic of Egypt
A2: الهيئة العامة للرعاية الصحية | M2: General Authority of Health Care
A3: مجمع الفيروز الطبي | M3: AL Fayrouz Medical Complex
A6: مراقبة وتقييم عقد صيانة أجهزة الكلي الصناعي
A7: م | B7: البند | C7: التقييم (ربع سنوي)
C8: 3/2026 | D8: 6/2026 | E8: 9/2026 | F8: 12/2026
A9: 1 | B9: التزام الشركة بمواعيد زيارات الصيانة الوقائية بواقع زيارة واحدة كل ثلاثة اشهر | C9: 1 | D9: 1 | E9: 1
A10: 2 | B10: استجابة الشركة في حالة ابلاغ المستشفي عن عطل بارسال مهندس الصيانة لال 48 ساعة من ابلاغ العطل علي ان تكون طلبات الاصلاح بدون حد أقصي | C10: 1 | D10: 1 | E10: 1
A11: 3 | B11: اتمام عملية استيراد قطع الغيار الاصلية و الجديدة الغير متوفرة محليا خلال 4 يوم من تاريخ تحديد القطع التالفة | C11: 1 | D11: 1 | E11: 1
A12: 4 | B12: تدريب العاملين و المستخدمين للاجهزة الموجودة بهذا العقد | C12: 1 | D12: 1 | E12: 1
A13: 5 | B13: تقديم الشركة بعد كل زيارة وقائية و اصلاحية تقريرا مفصلا عن ما تم من اعمال | C13: 1 | D13: 1 | E13: 1
A14: النسبة الإجمالية | C14: =AVERAGE(C9:C13) -> 1 | D14: 1 | E14: 1 | F14: =AVERAGE(F9:F13) -> #DIV/0! | J14: =AVERAGE(J9:J13) -> #DIV/0! | K14: =AVERAGE(K9:K13) -> #DIV/0! | L14: =IFERROR(AVERAGE(L9:L13),"-") -> - | M14: =IFERROR(AVERAGE(M9:M13),"-") -> -

Sheet   Chart 
A1: جمهورية مصر العربية | M1: Arab Republic of Egypt
A2: الهيئة العامة للرعاية الصحية | M2: General Authority of Health Care
A3: مجمع الفيروز الطبي | M3: AL Fayrouz Medical Complex
A6: مراقبة وتقييم عقد صيانة أجهزة الكلي الصناعي
A8: البسط | B8: عدد بنود التقييم المحققة
A9: المقام | B9: إجمالي عدد بنود التقييم (المحددة)
A10: المستهدف | B10: 0.8
A12: الشهر | B12: البسط | C12: المقام | D12: النسبة
A13: 3/2026 | B13: =SUMPRODUCT(--('الكلي الصناعي'!$C$9:$C$13&""="1")) -> 5 | C13: =SUMPRODUCT(--('الكلي الصناعي'!$C$9:$C$13&""="1"))+SUMPRODUCT(--('الكلي الصناعي'!$C$9:$C$13&""="0")) -> 5 | D13: =IFERROR(B13/C13,"") -> 1
A14: 6/2026 | B14: =SUMPRODUCT(--('الكلي الصناعي'!$D$9:$D$13&""="1")) -> 5 | C14: =SUMPRODUCT(--('الكلي الصناعي'!$D$9:$D$13&""="1"))+SUMPRODUCT(--('الكلي الصناعي'!$D$9:$D$13&""="0")) -> 5 | D14: =IFERROR(B14/C14,"") -> 1
A15: 9/2026 | B15: =SUMPRODUCT(--('الكلي الصناعي'!$E$9:$E$13&""="1")) -> 5 | C15: =SUMPRODUCT(--('الكلي الصناعي'!$E$9:$E$13&""="1"))+SUMPRODUCT(--('الكلي الصناعي'!$E$9:$E$13&""="0")) -> 5 | D15: =IFERROR(B15/C15,"") -> 1
D16: =IFERROR(B16/C16,"")
D17: =IFERROR(B17/C17,"")
D18: =IFERROR(B18/C18,"")
D19: =IFERROR(B19/C19,"")
D20: =IFERROR(B20/C20,"")
D21: =IFERROR(B21/C21,"")
D22: =IFERROR(B22/C22,"")
D23: =IFERROR(B23/C23,"")
A24: إجمالي التقييم السنوي للعقد | D24: =AVERAGE(D13:D23) -> 1
A26: الشهر | B26: التحليل الوصفي | E26: الإجراء التصحيحي | K26: المسؤول عن التنفيذ | M26: المدة

Sheet اشعة متنقل
A1: جمهورية مصر العربية | M1: Arab Republic of Egypt
A2: الهيئة العامة للرعاية الصحية | M2: General Authority of Health Care
A3: مجمع الفيروز الطبي | M3: AL Fayrouz Medical Complex
A6: مراقبة وتقييم عقد صيانة اجهزة الاشعة المتنقلة
A7: م | B7: البند | C7: التقييم (ربع سنوي)
C8: 3/2026 | D8: 6/2026 | E8: 9/2026 | F8: 12/2026
A9: 1 | B9: التزام الشركة بمواعيد زيارات الصيانة الوقائية بواقع زيارة واحدة كل ثلاثة اشهر | C9: 1 | D9: 1 | E9: 1
A10: 2 | B10: استجابة الشركة في حالة ابلاغ المستشفي عن عطل بارسال مهندس الصيانة لال 48 ساعة من ابلاغ العطل علي ان تكون طلبات الاصلاح بدون حد أقصي | C10: 1 | D10: 1 | E10: 1
A11: 3 | B11: اتمام عملية استيراد قطع الغيار الاصلية و الجديدة الغير متوفرة محليا خلال 4 يوم من تاريخ تحديد القطع التالفة | C11: 1 | D11: 1 | E11: 1
A12: 4 | B12: تدريب العاملين و المستخدمين للاجهزة الموجودة بهذا العقد | C12: 1 | D12: 1 | E12: 1
A13: 5 | B13: تقديم الشركة بعد كل زيارة وقائية و اصلاحية تقريرا مفصلا عن ما تم من اعمال | C13: 1 | D13: 1 | E13: 1
A14: النسبة الإجمالية | C14: =AVERAGE(C9:C13) -> 1 | D14: =AVERAGE(D9:D13) -> 1 | E14: =AVERAGE(E9:E13) -> 1 | F14: =AVERAGE(F9:F13) -> #DIV/0! | G14: =IFERROR(AVERAGE(G9:G13),"-") -> - | H14: =IFERROR(AVERAGE(H9:H13),"-") -> - | I14: =AVERAGE(I9:I13) -> #DIV/0! | J14: =AVERAGE(J9:J13) -> #DIV/0! | K14: =AVERAGE(K9:K13) -> #DIV/0! | L14: =IFERROR(AVERAGE(L9:L13),"-") -> - | M14: =IFERROR(AVERAGE(M9:M13),"-") -> -

Sheet Chart 
A1: جمهورية مصر العربية | M1: Arab Republic of Egypt
A2: الهيئة العامة للرعاية الصحية | M2: General Authority of Health Care
A3: مجمع الفيروز الطبي | M3: AL Fayrouz Medical Complex
A6: مراقبة وتقييم عقد صيانة اجهزة الاشعة المتنقلة
A8: البسط | B8: عدد بنود التقييم المحققة
A9: المقام | B9: إجمالي عدد بنود التقييم (المحددة)
A10: المستهدف | B10: 0.8
A12: الشهر | B12: البسط | C12: المقام | D12: النسبة
A13: 3/2026 | B13: =SUMPRODUCT(--('اشعة متنقل'!$C$9:$C$13&""="1")) -> 5 | C13: =SUMPRODUCT(--('اشعة متنقل'!$C$9:$C$13&""="1"))+SUMPRODUCT(--('اشعة متنقل'!$C$9:$C$13&""="0")) -> 5 | D13: =IFERROR(B13/C13,"") -> 1
A14: 6/2026 | B14: =SUMPRODUCT(--('اشعة متنقل'!$D$9:$D$13&""="1")) -> 5 | C14: =SUMPRODUCT(--('اشعة متنقل'!$D$9:$D$13&""="1"))+SUMPRODUCT(--('اشعة متنقل'!$D$9:$D$13&""="0")) -> 5 | D14: =IFERROR(B14/C14,"") -> 1
A15: 9/2026 | B15: =SUMPRODUCT(--('اشعة متنقل'!$E$9:$E$13&""="1")) -> 5 | C15: =SUMPRODUCT(--('اشعة متنقل'!$E$9:$E$13&""="1"))+SUMPRODUCT(--('اشعة متنقل'!$E$9:$E$13&""="0")) -> 5 | D15: =IFERROR(B15/C15,"") -> 1
D16: =IFERROR(B16/C16,"")
D17: =IFERROR(B17/C17,"")
D18: =IFERROR(B18/C18,"")
D19: =IFERROR(B19/C19,"")
D20: =IFERROR(B20/C20,"")
D21: =IFERROR(B21/C21,"")
D22: =IFERROR(B22/C22,"")
D23: =IFERROR(B23/C23,"")
A24: إجمالي التقييم السنوي للعقد | D24: =AVERAGE(D13:D23) -> 1
A26: الشهر | B26: التحليل الوصفي | E26: الإجراء التصحيحي | K26: المسؤول عن التنفيذ | M26: المدة

Sheet تنفس صناعي
A1: جمهورية مصر العربية | M1: Arab Republic of Egypt
A2: الهيئة العامة للرعاية الصحية | M2: General Authority of Health Care
A3: مجمع الفيروز الطبي | M3: AL Fayrouz Medical Complex
A6: مراقبة وتقييم عقد صيانة اجهزة التنفس الصناعي
A7: م | B7: البند | C7: التقييم (ربع سنوي)
C8: 3/2026 | D8: 6/2026 | E8: 9/2026 | F8: 12/2026
A9: 1 | B9: التزام الشركة بمواعيد زيارات الصيانة الوقائية بواقع زيارة واحدة كل ثلاثة اشهر | C9: 1 | D9: 1 | E9: 1
A10: 2 | B10: استجابة الشركة في حالة ابلاغ المستشفي عن عطل بارسال مهندس الصيانة لال 48 ساعة من ابلاغ العطل علي ان تكون طلبات الاصلاح بدون حد أقصي | C10: 1 | D10: 1 | E10: 1
A11: 3 | B11: اتمام عملية استيراد قطع الغيار الاصلية و الجديدة الغير متوفرة محليا خلال 4 يوم من تاريخ تحديد القطع التالفة | C11: 1 | D11: 1 | E11: 1
A12: 4 | B12: تدريب العاملين و المستخدمين للاجهزة الموجودة بهذا العقد | C12: 1 | D12: 1 | E12: 1
A13: 5 | B13: تقديم الشركة بعد كل زيارة وقائية و اصلاحية تقريرا مفصلا عن ما تم من اعمال | C13: 1 | D13: 1 | E13: 1
A14: النسبة الإجمالية | C14: =AVERAGE(C9:C13) -> 1 | D14: =AVERAGE(D9:D13) -> 1 | E14: =AVERAGE(E9:E13) -> 1 | F14: =AVERAGE(F9:F13) -> #DIV/0! | G14: =IFERROR(AVERAGE(G9:G13),"-") -> - | H14: =IFERROR(AVERAGE(H9:H13),"-") -> - | I14: =AVERAGE(I9:I13) -> #DIV/0! | J14: =AVERAGE(J9:J13) -> #DIV/0! | K14: =AVERAGE(K9:K13) -> #DIV/0! | L14: =IFERROR(AVERAGE(L9:L13),"-") -> - | M14: =IFERROR(AVERAGE(M9:M13),"-") -> -

Sheet Chart  
A1: جمهورية مصر العربية
A2: الهيئة العامة للرعاية الصحية
A3: مجمع الفيروز الطبي
A6: مراقبة وتقييم عقد صيانة اجهزة التنفس الصناعي
A8: البسط | B8: عدد بنود التقييم المحققة
A9: المقام | B9: إجمالي عدد بنود التقييم (المحددة)
A10: المستهدف | B10: 0.8
A12: الشهر | B12: البسط | C12: المقام | D12: النسبة
A13: 3/2026 | B13: =SUMPRODUCT(--('تنفس صناعي'!$C$9:$C$13&""="1")) -> 5 | C13: =SUMPRODUCT(--('تنفس صناعي'!$C$9:$C$13&""="1"))+SUMPRODUCT(--('تنفس صناعي'!$C$9:$C$13&""="0")) -> 5 | D13: =IFERROR(B13/C13,"") -> 1
A14: 6/2026 | B14: =SUMPRODUCT(--('تنفس صناعي'!$D$9:$D$13&""="1")) -> 5 | C14: =SUMPRODUCT(--('تنفس صناعي'!$D$9:$D$13&""="1"))+SUMPRODUCT(--('تنفس صناعي'!$D$9:$D$13&""="0")) -> 5 | D14: =IFERROR(B14/C14,"") -> 1
A15: 9/2026 | B15: =SUMPRODUCT(--('تنفس صناعي'!$E$9:$E$13&""="1")) -> 5 | C15: =SUMPRODUCT(--('تنفس صناعي'!$E$9:$E$13&""="1"))+SUMPRODUCT(--('تنفس صناعي'!$E$9:$E$13&""="0")) -> 5 | D15: =IFERROR(B15/C15,"") -> 1
D16: =IFERROR(B16/C16,"")
D17: =IFERROR(B17/C17,"")
D18: =IFERROR(B18/C18,"")
D19: =IFERROR(B19/C19,"")
D20: =IFERROR(B20/C20,"")
D21: =IFERROR(B21/C21,"")
D22: =IFERROR(B22/C22,"")
D23: =IFERROR(B23/C23,"")
A24: إجمالي التقييم السنوي للعقد | D24: =AVERAGE(D13:D23) -> 1
A26: الشهر | B26: التحليل الوصفي | E26: الإجراء التصحيحي | K26: المسؤول عن التنفيذ | M26: المدة

Sheet اشعة ماموجرام 
A1: جمهورية مصر العربية | M1: Arab Republic of Egypt
A2: الهيئة العامة للرعاية الصحية | M2: General Authority of Health Care
A3: مجمع الفيروز الطبي | M3: AL Fayrouz Medical Complex
A6: مراقبة وتقييم عقد صيانة جهاز اشعة الماموجرام
A7: م | B7: البند | C7: التقييم (ربع سنوي)
C8: 3/2026 | D8: 6/2026 | E8: 9/2026 | F8: 12/2026
A9: 1 | B9: التزام الشركة بمواعيد زيارات الصيانة الوقائية بواقع زيارة واحدة كل ثلاثة اشهر | C9: 1 | D9: 1 | E9: 1
A10: 2 | B10: استجابة الشركة في حالة ابلاغ المستشفي عن عطل بارسال مهندس الصيانة لال 48 ساعة من ابلاغ العطل علي ان تكون طلبات الاصلاح بدون حد أقصي | C10: 1 | D10: 1 | E10: 1
A11: 3 | B11: اتمام عملية استيراد قطع الغيار الاصلية و الجديدة الغير متوفرة محليا خلال 4 يوم من تاريخ تحديد القطع التالفة | C11: 1 | D11: 1 | E11: 1
A12: 4 | B12: تدريب العاملين و المستخدمين للاجهزة الموجودة بهذا العقد | C12: 1 | D12: 1 | E12: 1
A13: 5 | B13: تقديم الشركة بعد كل زيارة وقائية و اصلاحية تقريرا مفصلا عن ما تم من اعمال | C13: 1 | D13: 1 | E13: 1
A14: النسبة الإجمالية | C14: =AVERAGE(C9:C13) -> 1 | D14: =AVERAGE(D9:D13) -> 1 | E14: =AVERAGE(E9:E13) -> 1 | F14: =AVERAGE(F9:F13) -> #DIV/0! | G14: =IFERROR(AVERAGE(G9:G13),"-") -> - | H14: =IFERROR(AVERAGE(H9:H13),"-") -> - | L14: =IFERROR(AVERAGE(L9:L13),"-") -> - | M14: =IFERROR(AVERAGE(M9:M13),"-") -> -

Sheet  Chart  
A1: جمهورية مصر العربية | M1: Arab Republic of Egypt
A2: الهيئة العامة للرعاية الصحية | M2: General Authority of Health Care
A3: مجمع الفيروز الطبي | M3: AL Fayrouz Medical Complex
A6: مراقبة وتقييم عقد صيانة جهاز اشعة الماموجرام
A8: البسط | B8: عدد بنود التقييم المحققة
A9: المقام | B9: إجمالي عدد بنود التقييم (المحددة)
A10: المستهدف | B10: 0.8
A12: الشهر | B12: البسط | C12: المقام | D12: النسبة
A13: 3/2026 | B13: =SUMPRODUCT(--('اشعة ماموجرام '!$C$9:$C$13&""="1")) -> 5 | C13: =SUMPRODUCT(--('اشعة ماموجرام '!$C$9:$C$13&""="1"))+SUMPRODUCT(--('اشعة ماموجرام '!$C$9:$C$13&""="0")) -> 5 | D13: =IFERROR(B13/C13,"") -> 1
A14: 6/2026 | B14: =SUMPRODUCT(--('اشعة ماموجرام '!$D$9:$D$13&""="1")) -> 5 | C14: =SUMPRODUCT(--('اشعة ماموجرام '!$D$9:$D$13&""="1"))+SUMPRODUCT(--('اشعة ماموجرام '!$D$9:$D$13&""="0")) -> 5 | D14: =IFERROR(B14/C14,"") -> 1
A15: 9/2026 | B15: =SUMPRODUCT(--('اشعة ماموجرام '!$E$9:$E$13&""="1")) -> 5 | C15: =SUMPRODUCT(--('اشعة ماموجرام '!$E$9:$E$13&""="1"))+SUMPRODUCT(--('اشعة ماموجرام '!$E$9:$E$13&""="0")) -> 5 | D15: =IFERROR(B15/C15,"") -> 1
D16: =IFERROR(B16/C16,"")
D17: =IFERROR(B17/C17,"")
D18: =IFERROR(B18/C18,"")
D19: =IFERROR(B19/C19,"")
D20: =IFERROR(B20/C20,"")
D21: =IFERROR(B21/C21,"")
D22: =IFERROR(B22/C22,"")
D23: =IFERROR(B23/C23,"")
A24: إجمالي التقييم السنوي للعقد | D24: =AVERAGE(D13:D23) -> 1
A26: الشهر | B26: التحليل الوصفي | E26: الإجراء التصحيحي | K26: المسؤول عن التنفيذ | M26: المدة

Sheet التعقيم 
A1: جمهورية مصر العربية | M1: Arab Republic of Egypt
A2: الهيئة العامة للرعاية الصحية | M2: General Authority of Health Care
A3: مجمع الفيروز الطبي | M3: AL Fayrouz Medical Complex
A6: مراقبة وتقييم عقد صيانة اجهزة التعقيم
A7: م | B7: البند | C7: التقييم (ربع سنوي)
C8: 3/2026 | D8: 6/2026 | E8: 9/2026 | F8: 12/2026
A9: 1 | B9: التزام الشركة بمواعيد زيارات الصيانة الوقائية بواقع زيارة واحدة كل ثلاثة اشهر | C9: 1 | D9: 1 | E9: 1
A10: 2 | B10: استجابة الشركة في حالة ابلاغ المستشفي عن عطل بارسال مهندس الصيانة لال 48 ساعة من ابلاغ العطل علي ان تكون طلبات الاصلاح بدون حد أقصي | C10: 1 | D10: 1 | E10: 1
A11: 3 | B11: اتمام عملية استيراد قطع الغيار الاصلية و الجديدة الغير متوفرة محليا خلال 4 يوم من تاريخ تحديد القطع التالفة | C11: 1 | D11: 0 | E11: 1
A12: 4 | B12: تدريب العاملين و المستخدمين للاجهزة الموجودة بهذا العقد | C12: 1 | D12: 1 | E12: 1
A13: 5 | B13: تقديم الشركة بعد كل زيارة وقائية و اصلاحية تقريرا مفصلا عن ما تم من اعمال | C13: 1 | D13: 1 | E13: 1
A14: النسبة الإجمالية | C14: =AVERAGE(C9:C13) -> 1 | D14: =AVERAGE(D9:D13) -> 0.8 | E14: =AVERAGE(E9:E13) -> 1 | F14: =AVERAGE(F9:F13) -> #DIV/0! | G14: =IFERROR(AVERAGE(G9:G13),"-") -> - | H14: =IFERROR(AVERAGE(H9:H13),"-") -> - | I14: =AVERAGE(I9:I13) -> #DIV/0! | J14: =AVERAGE(J9:J13) -> #DIV/0! | K14: =AVERAGE(K9:K13) -> #DIV/0! | L14: =IFERROR(AVERAGE(L9:L13),"-") -> - | M14: =IFERROR(AVERAGE(M9:M13),"-") -> -

Sheet Chart
A1: جمهورية مصر العربية | M1: Arab Republic of Egypt
A2: الهيئة العامة للرعاية الصحية | M2: General Authority of Health Care
A3: مجمع الفيروز الطبي | M3: AL Fayrouz Medical Complex
A6: مراقبة وتقييم عقد صيانة اجهزة التعقيم
A8: البسط | B8: عدد بنود التقييم المحققة
A9: المقام | B9: إجمالي عدد بنود التقييم (المحددة)
A10: المستهدف | B10: 0.8
A12: الشهر | B12: البسط | C12: المقام | D12: النسبة
A13: 3/2026 | B13: =SUMPRODUCT(--('التعقيم '!$C$9:$C$13&""="1")) -> 5 | C13: =SUMPRODUCT(--('التعقيم '!$C$9:$C$13&""="1"))+SUMPRODUCT(--('التعقيم '!$C$9:$C$13&""="0")) -> 5 | D13: =IFERROR(B13/C13,"") -> 1
A14: 6/2026 | B14: =SUMPRODUCT(--('التعقيم '!$D$9:$D$13&""="1")) -> 4 | C14: =SUMPRODUCT(--('التعقيم '!$D$9:$D$13&""="1"))+SUMPRODUCT(--('التعقيم '!$D$9:$D$13&""="0")) -> 5 | D14: =IFERROR(B14/C14,"") -> 0.8
A15: 9/2026 | B15: =SUMPRODUCT(--('التعقيم '!$E$9:$E$13&""="1")) -> 5 | C15: =SUMPRODUCT(--('التعقيم '!$E$9:$E$13&""="1"))+SUMPRODUCT(--('التعقيم '!$E$9:$E$13&""="0")) -> 5 | D15: =IFERROR(B15/C15,"") -> 1
D16: =IFERROR(B16/C16,"")
D17: =IFERROR(B17/C17,"")
D18: =IFERROR(B18/C18,"")
D19: =IFERROR(B19/C19,"")
D20: =IFERROR(B20/C20,"")
D21: =IFERROR(B21/C21,"")
D22: =IFERROR(B22/C22,"")
D23: =IFERROR(B23/C23,"")
A24: إجمالي التقييم السنوي للعقد | D24: =AVERAGE(D13:D23) -> 0.93333333
